===== Bienvenido a Quito-Clima =====
===== Bienvenido a Quito-Clima =====
===== Bienvenido a Quito-Clima =====
===== Bienvenido a Quito-Clima =====
===== Bienvenido a Quito-Clima =====
===== Bienvenido a Quito-Clima =====
===== Bienvenido a Quito-Clima =====
===== Bienvenido a Quito-Clima =====
===== Bienvenido a Quito-Clima =====
===== Bienvenido a Quito-Clima =====
===== Bienvenido a Quito-Clima =====
===== Bienvenido a Quito-Clima =====
===== Bienvenido a Quito-Clima =====
===== Bienvenido a Quito-Clima =====
===== Bienvenido a Quito-Clima =====
===== Bienvenido a Quito-Clima =====
===== Bienvenido a Quito-Clima =====
===== Bienvenido a Quito-Clima =====
===== Bienvenido a Quito-Clima =====
===== Bienvenido a Quito-Clima =====
===== Bienvenido a Quito-Clima =====
===== Bienvenido a Quito-Clima =====
===== Bienvenido a Quito-Clima =====
===== Bienvenido a Quito-Clima =====
===== Bienvenido a Quito-Clima =====
===== Bienvenido a Quito-Clima =====
===== Bienvenido a Quito-Clima =====
===== Bienvenido a Quito-Clima =====
===== Bienvenido a Quito-Clima =====
===== Bienvenido a Quito-Clima =====
===== Bienvenido a Quito-Clima =====
===== Bienvenido a Quito-Clima =====
===== Bienvenido a Quito-Clima =====
===== Bienvenido a Quito-Clima =====
===== Bienvenido a Quito-Clima =====
===== Bienvenido a Quito-Clima =====
===== Bienvenido a Quito-Clima =====
===== Bienvenido a Quito-Clima =====
===== Bienvenido a Quito-Clima =====
===== Bienvenido a Quito-Clima =====
===== Bienvenido a Quito-Clima =====
===== Bienvenido a Quito-Clima =====
===== Bienvenido a Quito-Clima =====
Traceback (most recent call last):
  File "/usr/lib/python3/dist-packages/urllib3/connection.py", line 169, in _new_conn
    conn = connection.create_connection(
  File "/usr/lib/python3/dist-packages/urllib3/util/connection.py", line 96, in create_connection
    raise err
  File "/usr/lib/python3/dist-packages/urllib3/util/connection.py", line 86, in create_connection
    sock.connect(sa)
OSError: [Errno 101] Network is unreachable

During handling of the above exception, another exception occurred:

Traceback (most recent call last):
  File "/usr/lib/python3/dist-packages/urllib3/connectionpool.py", line 700, in urlopen
    httplib_response = self._make_request(
  File "/usr/lib/python3/dist-packages/urllib3/connectionpool.py", line 383, in _make_request
    self._validate_conn(conn)
  File "/usr/lib/python3/dist-packages/urllib3/connectionpool.py", line 1017, in _validate_conn
    conn.connect()
  File "/usr/lib/python3/dist-packages/urllib3/connection.py", line 353, in connect
    conn = self._new_conn()
  File "/usr/lib/python3/dist-packages/urllib3/connection.py", line 181, in _new_conn
    raise NewConnectionError(
urllib3.exceptions.NewConnectionError: <urllib3.connection.HTTPSConnection object at 0x754f7a9c61d0>: Failed to establish a new connection: [Errno 101] Network is unreachable

During handling of the above exception, another exception occurred:

Traceback (most recent call last):
  File "/home/kikeykarina/.local/lib/python3.10/site-packages/requests/adapters.py", line 486, in send
    resp = conn.urlopen(
  File "/usr/lib/python3/dist-packages/urllib3/connectionpool.py", line 756, in urlopen
    retries = retries.increment(
  File "/usr/lib/python3/dist-packages/urllib3/util/retry.py", line 574, in increment
    raise MaxRetryError(_pool, url, error or ResponseError(cause))
urllib3.exceptions.MaxRetryError: HTTPSConnectionPool(host='api.openweathermap.org', port=443): Max retries exceeded with url: /data/2.5/weather?lat=-0.2299&lon=-78.5249&appid=2d0126e794e76199a4aecf1ac87d4f78 (Caused by NewConnectionError('<urllib3.connection.HTTPSConnection object at 0x754f7a9c61d0>: Failed to establish a new connection: [Errno 101] Network is unreachable'))

During handling of the above exception, another exception occurred:

Traceback (most recent call last):
  File "/home/kikeykarina/Documents/Universidad/Arquitectura/bimestre2/proyecto/CityWeather/main.py", line 76, in <module>
    main()
  File "/home/kikeykarina/Documents/Universidad/Arquitectura/bimestre2/proyecto/CityWeather/main.py", line 66, in main
    quito_weather = get_weather(lat=QUITO_LAT, lon=QUITO_LONGITUDE, api=API_KEY)
  File "/home/kikeykarina/Documents/Universidad/Arquitectura/bimestre2/proyecto/CityWeather/main.py", line 15, in get_weather
    response = requests.get(url)
  File "/home/kikeykarina/.local/lib/python3.10/site-packages/requests/api.py", line 73, in get
    return request("get", url, params=params, **kwargs)
  File "/home/kikeykarina/.local/lib/python3.10/site-packages/requests/api.py", line 59, in request
    return session.request(method=method, url=url, **kwargs)
  File "/home/kikeykarina/.local/lib/python3.10/site-packages/requests/sessions.py", line 589, in request
    resp = self.send(prep, **send_kwargs)
  File "/home/kikeykarina/.local/lib/python3.10/site-packages/requests/sessions.py", line 703, in send
    r = adapter.send(request, **kwargs)
  File "/home/kikeykarina/.local/lib/python3.10/site-packages/requests/adapters.py", line 519, in send
    raise ConnectionError(e, request=request)
requests.exceptions.ConnectionError: HTTPSConnectionPool(host='api.openweathermap.org', port=443): Max retries exceeded with url: /data/2.5/weather?lat=-0.2299&lon=-78.5249&appid=2d0126e794e76199a4aecf1ac87d4f78 (Caused by NewConnectionError('<urllib3.connection.HTTPSConnection object at 0x754f7a9c61d0>: Failed to establish a new connection: [Errno 101] Network is unreachable'))
===== Bienvenido a Quito-Clima =====
===== Bienvenido a Quito-Clima =====
===== Bienvenido a Quito-Clima =====
===== Bienvenido a Quito-Clima =====
===== Bienvenido a Quito-Clima =====
===== Bienvenido a Quito-Clima =====
===== Bienvenido a Quito-Clima =====
===== Bienvenido a Quito-Clima =====
===== Bienvenido a Quito-Clima =====
===== Bienvenido a Quito-Clima =====
Traceback (most recent call last):
  File "/usr/lib/python3/dist-packages/urllib3/connection.py", line 169, in _new_conn
    conn = connection.create_connection(
  File "/usr/lib/python3/dist-packages/urllib3/util/connection.py", line 73, in create_connection
    for res in socket.getaddrinfo(host, port, family, socket.SOCK_STREAM):
  File "/usr/lib/python3.10/socket.py", line 955, in getaddrinfo
    for res in _socket.getaddrinfo(host, port, family, type, proto, flags):
socket.gaierror: [Errno -3] Temporary failure in name resolution

During handling of the above exception, another exception occurred:

Traceback (most recent call last):
  File "/usr/lib/python3/dist-packages/urllib3/connectionpool.py", line 700, in urlopen
    httplib_response = self._make_request(
  File "/usr/lib/python3/dist-packages/urllib3/connectionpool.py", line 383, in _make_request
    self._validate_conn(conn)
  File "/usr/lib/python3/dist-packages/urllib3/connectionpool.py", line 1017, in _validate_conn
    conn.connect()
  File "/usr/lib/python3/dist-packages/urllib3/connection.py", line 353, in connect
    conn = self._new_conn()
  File "/usr/lib/python3/dist-packages/urllib3/connection.py", line 181, in _new_conn
    raise NewConnectionError(
urllib3.exceptions.NewConnectionError: <urllib3.connection.HTTPSConnection object at 0x72e784c921d0>: Failed to establish a new connection: [Errno -3] Temporary failure in name resolution

During handling of the above exception, another exception occurred:

Traceback (most recent call last):
  File "/home/kikeykarina/.local/lib/python3.10/site-packages/requests/adapters.py", line 486, in send
    resp = conn.urlopen(
  File "/usr/lib/python3/dist-packages/urllib3/connectionpool.py", line 756, in urlopen
    retries = retries.increment(
  File "/usr/lib/python3/dist-packages/urllib3/util/retry.py", line 574, in increment
    raise MaxRetryError(_pool, url, error or ResponseError(cause))
urllib3.exceptions.MaxRetryError: HTTPSConnectionPool(host='api.openweathermap.org', port=443): Max retries exceeded with url: /data/2.5/weather?lat=-0.2299&lon=-78.5249&appid=2d0126e794e76199a4aecf1ac87d4f78 (Caused by NewConnectionError('<urllib3.connection.HTTPSConnection object at 0x72e784c921d0>: Failed to establish a new connection: [Errno -3] Temporary failure in name resolution'))

During handling of the above exception, another exception occurred:

Traceback (most recent call last):
  File "/home/kikeykarina/Documents/Universidad/Arquitectura/bimestre2/proyecto/CityWeather/main.py", line 76, in <module>
    main()
  File "/home/kikeykarina/Documents/Universidad/Arquitectura/bimestre2/proyecto/CityWeather/main.py", line 66, in main
    quito_weather = get_weather(lat=QUITO_LAT, lon=QUITO_LONGITUDE, api=API_KEY)
  File "/home/kikeykarina/Documents/Universidad/Arquitectura/bimestre2/proyecto/CityWeather/main.py", line 15, in get_weather
    response = requests.get(url)
  File "/home/kikeykarina/.local/lib/python3.10/site-packages/requests/api.py", line 73, in get
    return request("get", url, params=params, **kwargs)
  File "/home/kikeykarina/.local/lib/python3.10/site-packages/requests/api.py", line 59, in request
    return session.request(method=method, url=url, **kwargs)
  File "/home/kikeykarina/.local/lib/python3.10/site-packages/requests/sessions.py", line 589, in request
    resp = self.send(prep, **send_kwargs)
  File "/home/kikeykarina/.local/lib/python3.10/site-packages/requests/sessions.py", line 703, in send
    r = adapter.send(request, **kwargs)
  File "/home/kikeykarina/.local/lib/python3.10/site-packages/requests/adapters.py", line 519, in send
    raise ConnectionError(e, request=request)
requests.exceptions.ConnectionError: HTTPSConnectionPool(host='api.openweathermap.org', port=443): Max retries exceeded with url: /data/2.5/weather?lat=-0.2299&lon=-78.5249&appid=2d0126e794e76199a4aecf1ac87d4f78 (Caused by NewConnectionError('<urllib3.connection.HTTPSConnection object at 0x72e784c921d0>: Failed to establish a new connection: [Errno -3] Temporary failure in name resolution'))
===== Bienvenido a Quito-Clima =====
===== Bienvenido a Quito-Clima =====
===== Bienvenido a Quito-Clima =====
===== Bienvenido a Quito-Clima =====
Traceback (most recent call last):
  File "/usr/lib/python3/dist-packages/urllib3/connection.py", line 169, in _new_conn
    conn = connection.create_connection(
  File "/usr/lib/python3/dist-packages/urllib3/util/connection.py", line 73, in create_connection
    for res in socket.getaddrinfo(host, port, family, socket.SOCK_STREAM):
  File "/usr/lib/python3.10/socket.py", line 955, in getaddrinfo
    for res in _socket.getaddrinfo(host, port, family, type, proto, flags):
socket.gaierror: [Errno -3] Temporary failure in name resolution

During handling of the above exception, another exception occurred:

Traceback (most recent call last):
  File "/usr/lib/python3/dist-packages/urllib3/connectionpool.py", line 700, in urlopen
    httplib_response = self._make_request(
  File "/usr/lib/python3/dist-packages/urllib3/connectionpool.py", line 383, in _make_request
    self._validate_conn(conn)
  File "/usr/lib/python3/dist-packages/urllib3/connectionpool.py", line 1017, in _validate_conn
    conn.connect()
  File "/usr/lib/python3/dist-packages/urllib3/connection.py", line 353, in connect
    conn = self._new_conn()
  File "/usr/lib/python3/dist-packages/urllib3/connection.py", line 181, in _new_conn
    raise NewConnectionError(
urllib3.exceptions.NewConnectionError: <urllib3.connection.HTTPSConnection object at 0x7fdaf37c21d0>: Failed to establish a new connection: [Errno -3] Temporary failure in name resolution

During handling of the above exception, another exception occurred:

Traceback (most recent call last):
  File "/home/kikeykarina/.local/lib/python3.10/site-packages/requests/adapters.py", line 486, in send
    resp = conn.urlopen(
  File "/usr/lib/python3/dist-packages/urllib3/connectionpool.py", line 756, in urlopen
    retries = retries.increment(
  File "/usr/lib/python3/dist-packages/urllib3/util/retry.py", line 574, in increment
    raise MaxRetryError(_pool, url, error or ResponseError(cause))
urllib3.exceptions.MaxRetryError: HTTPSConnectionPool(host='api.openweathermap.org', port=443): Max retries exceeded with url: /data/2.5/weather?lat=-0.2299&lon=-78.5249&appid=2d0126e794e76199a4aecf1ac87d4f78 (Caused by NewConnectionError('<urllib3.connection.HTTPSConnection object at 0x7fdaf37c21d0>: Failed to establish a new connection: [Errno -3] Temporary failure in name resolution'))

During handling of the above exception, another exception occurred:

Traceback (most recent call last):
  File "/home/kikeykarina/Documents/Universidad/Arquitectura/bimestre2/proyecto/CityWeather/main.py", line 76, in <module>
    main()
  File "/home/kikeykarina/Documents/Universidad/Arquitectura/bimestre2/proyecto/CityWeather/main.py", line 66, in main
    quito_weather = get_weather(lat=QUITO_LAT, lon=QUITO_LONGITUDE, api=API_KEY)
  File "/home/kikeykarina/Documents/Universidad/Arquitectura/bimestre2/proyecto/CityWeather/main.py", line 15, in get_weather
    response = requests.get(url)
  File "/home/kikeykarina/.local/lib/python3.10/site-packages/requests/api.py", line 73, in get
    return request("get", url, params=params, **kwargs)
  File "/home/kikeykarina/.local/lib/python3.10/site-packages/requests/api.py", line 59, in request
    return session.request(method=method, url=url, **kwargs)
  File "/home/kikeykarina/.local/lib/python3.10/site-packages/requests/sessions.py", line 589, in request
    resp = self.send(prep, **send_kwargs)
  File "/home/kikeykarina/.local/lib/python3.10/site-packages/requests/sessions.py", line 703, in send
    r = adapter.send(request, **kwargs)
  File "/home/kikeykarina/.local/lib/python3.10/site-packages/requests/adapters.py", line 519, in send
    raise ConnectionError(e, request=request)
requests.exceptions.ConnectionError: HTTPSConnectionPool(host='api.openweathermap.org', port=443): Max retries exceeded with url: /data/2.5/weather?lat=-0.2299&lon=-78.5249&appid=2d0126e794e76199a4aecf1ac87d4f78 (Caused by NewConnectionError('<urllib3.connection.HTTPSConnection object at 0x7fdaf37c21d0>: Failed to establish a new connection: [Errno -3] Temporary failure in name resolution'))
===== Bienvenido a Quito-Clima =====
===== Bienvenido a Quito-Clima =====
